Connection to master succeeded
http://127.0.0.1:8000/get_chunk_servers
{'chunk_id': 'acee7e74-0f8e-405d-aac3-5f1c01708e22', 'request_type': 'write'}
The get_chunk_servers_json is {'chunk_servers': [{'session_id': 'b52cd8ef-6c14-42e9-bffd-caffa622f1d4', 'ipv4_address': 'http://localhost:8099'}, {'session_id': 'fdce4e6b-3c05-4779-ad2a-698d46f2fa41', 'ipv4_address': 'http://localhost:8097'}, {'session_id': '70a53c1e-fa3f-4bc5-934b-324398e7a094', 'ipv4_address': 'http://localhost:8098'}]}
Chunk server list is [{'session_id': 'b52cd8ef-6c14-42e9-bffd-caffa622f1d4', 'ipv4_address': 'http://localhost:8099'}, {'session_id': 'fdce4e6b-3c05-4779-ad2a-698d46f2fa41', 'ipv4_address': 'http://localhost:8097'}, {'session_id': '70a53c1e-fa3f-4bc5-934b-324398e7a094', 'ipv4_address': 'http://localhost:8098'}]
{'session_id': 'b52cd8ef-6c14-42e9-bffd-caffa622f1d4', 'ipv4_address': 'http://localhost:8099'}
http://localhost:8099/heartbeat
[acee7e74-0f8e-405d-aac3-5f1c01708e22]write_chunk request is successful
http://127.0.0.1:8000/get_chunk_servers
{'chunk_id': '8ee50c48-ed83-4ec2-a9ea-4efce1b67228', 'request_type': 'write'}
The get_chunk_servers_json is {'chunk_servers': [{'session_id': '70a53c1e-fa3f-4bc5-934b-324398e7a094', 'ipv4_address': 'http://localhost:8098'}, {'session_id': 'fdce4e6b-3c05-4779-ad2a-698d46f2fa41', 'ipv4_address': 'http://localhost:8097'}, {'session_id': 'b52cd8ef-6c14-42e9-bffd-caffa622f1d4', 'ipv4_address': 'http://localhost:8099'}]}
Chunk server list is [{'session_id': '70a53c1e-fa3f-4bc5-934b-324398e7a094', 'ipv4_address': 'http://localhost:8098'}, {'session_id': 'fdce4e6b-3c05-4779-ad2a-698d46f2fa41', 'ipv4_address': 'http://localhost:8097'}, {'session_id': 'b52cd8ef-6c14-42e9-bffd-caffa622f1d4', 'ipv4_address': 'http://localhost:8099'}]
{'session_id': '70a53c1e-fa3f-4bc5-934b-324398e7a094', 'ipv4_address': 'http://localhost:8098'}
http://localhost:8098/heartbeat
[8ee50c48-ed83-4ec2-a9ea-4efce1b67228]write_chunk request is successful
http://127.0.0.1:8000/get_chunk_servers
{'chunk_id': '13d303d3-831b-4342-95b1-180849a5f5fe', 'request_type': 'write'}
Traceback (most recent call last):
  File "/opt/homebrew/lib/python3.11/site-packages/urllib3/connectionpool.py", line 714, in urlopen
    httplib_response = self._make_request(
                       ^^^^^^^^^^^^^^^^^^^
  File "/opt/homebrew/lib/python3.11/site-packages/urllib3/connectionpool.py", line 466, in _make_request
    six.raise_from(e, None)
  File "<string>", line 3, in raise_from
  File "/opt/homebrew/lib/python3.11/site-packages/urllib3/connectionpool.py", line 461, in _make_request
    httplib_response = conn.getresponse()
                       ^^^^^^^^^^^^^^^^^^
  File "/opt/homebrew/Cellar/python@3.11/3.11.5/Frameworks/Python.framework/Versions/3.11/lib/python3.11/http/client.py", line 1378, in getresponse
    response.begin()
  File "/opt/homebrew/Cellar/python@3.11/3.11.5/Frameworks/Python.framework/Versions/3.11/lib/python3.11/http/client.py", line 318, in begin
    version, status, reason = self._read_status()
                              ^^^^^^^^^^^^^^^^^^^
  File "/opt/homebrew/Cellar/python@3.11/3.11.5/Frameworks/Python.framework/Versions/3.11/lib/python3.11/http/client.py", line 287, in _read_status
    raise RemoteDisconnected("Remote end closed connection without"
http.client.RemoteDisconnected: Remote end closed connection without response

During handling of the above exception, another exception occurred:

Traceback (most recent call last):
  File "/opt/homebrew/lib/python3.11/site-packages/requests/adapters.py", line 486, in send
    resp = conn.urlopen(
           ^^^^^^^^^^^^^
  File "/opt/homebrew/lib/python3.11/site-packages/urllib3/connectionpool.py", line 798, in urlopen
    retries = retries.increment(
              ^^^^^^^^^^^^^^^^^^
  File "/opt/homebrew/lib/python3.11/site-packages/urllib3/util/retry.py", line 550, in increment
    raise six.reraise(type(error), error, _stacktrace)
          ^^^^^^^^^^^^^^^^^^^^^^^^^^^^^^^^^^^^^^^^^^^^
  File "/opt/homebrew/lib/python3.11/site-packages/urllib3/packages/six.py", line 769, in reraise
    raise value.with_traceback(tb)
  File "/opt/homebrew/lib/python3.11/site-packages/urllib3/connectionpool.py", line 714, in urlopen
    httplib_response = self._make_request(
                       ^^^^^^^^^^^^^^^^^^^
  File "/opt/homebrew/lib/python3.11/site-packages/urllib3/connectionpool.py", line 466, in _make_request
    six.raise_from(e, None)
  File "<string>", line 3, in raise_from
  File "/opt/homebrew/lib/python3.11/site-packages/urllib3/connectionpool.py", line 461, in _make_request
    httplib_response = conn.getresponse()
                       ^^^^^^^^^^^^^^^^^^
  File "/opt/homebrew/Cellar/python@3.11/3.11.5/Frameworks/Python.framework/Versions/3.11/lib/python3.11/http/client.py", line 1378, in getresponse
    response.begin()
  File "/opt/homebrew/Cellar/python@3.11/3.11.5/Frameworks/Python.framework/Versions/3.11/lib/python3.11/http/client.py", line 318, in begin
    version, status, reason = self._read_status()
                              ^^^^^^^^^^^^^^^^^^^
  File "/opt/homebrew/Cellar/python@3.11/3.11.5/Frameworks/Python.framework/Versions/3.11/lib/python3.11/http/client.py", line 287, in _read_status
    raise RemoteDisconnected("Remote end closed connection without"
urllib3.exceptions.ProtocolError: ('Connection aborted.', RemoteDisconnected('Remote end closed connection without response'))

During handling of the above exception, another exception occurred:

Traceback (most recent call last):
  File "/Users/puneeth/Documents/software/side-projects/gfs-clone/client.py", line 132, in <module>
    create_file(f"blah-blah-{sys.argv[2]}.txt", len(stream), stream)
  File "/Users/puneeth/Documents/software/side-projects/gfs-clone/client.py", line 91, in create_file
    get_chunk_servers_json = requests.get(urljoin(client_config["gfs_server_info"]["ipv4_address"], "get_chunk_servers"), params={"chunk_id": chunk_id, "request_type": "write"}).json()
                             ^^^^^^^^^^^^^^^^^^^^^^^^^^^^^^^^^^^^^^^^^^^^^^^^^^^^^^^^^^^^^^^^^^^^^^^^^^^^^^^^^^^^^^^^^^^^^^^^^^^^^^^^^^^^^^^^^^^^^^^^^^^^^^^^^^^^^^^^^^^^^^^^^^^^
  File "/opt/homebrew/lib/python3.11/site-packages/requests/api.py", line 73, in get
    return request("get", url, params=params, **kwargs)
           ^^^^^^^^^^^^^^^^^^^^^^^^^^^^^^^^^^^^^^^^^^^^
  File "/opt/homebrew/lib/python3.11/site-packages/requests/api.py", line 59, in request
    return session.request(method=method, url=url, **kwargs)
           ^^^^^^^^^^^^^^^^^^^^^^^^^^^^^^^^^^^^^^^^^^^^^^^^^
  File "/opt/homebrew/lib/python3.11/site-packages/requests/sessions.py", line 589, in request
    resp = self.send(prep, **send_kwargs)
           ^^^^^^^^^^^^^^^^^^^^^^^^^^^^^^
  File "/opt/homebrew/lib/python3.11/site-packages/requests/sessions.py", line 703, in send
    r = adapter.send(request, **kwargs)
        ^^^^^^^^^^^^^^^^^^^^^^^^^^^^^^^
  File "/opt/homebrew/lib/python3.11/site-packages/requests/adapters.py", line 501, in send
    raise ConnectionError(err, request=request)
requests.exceptions.ConnectionError: ('Connection aborted.', RemoteDisconnected('Remote end closed connection without response'))
